<?xml version="1.0" ?>
<!-- =================================================================================== -->
<!-- |    This document was autogenerated by xacro from mecanum_bot.xacro              | -->
<!-- |    EDITING THIS FILE BY HAND IS NOT RECOMMENDED                                 | -->
<!-- =================================================================================== -->
<robot name="mecanum_bot">
  <!-- <link name="base_link"/> -->
  
  <!-- <material name="silver_default">
    <color rgba="0.700 0.700 0.700 1.000"/>
  </material>
  <material name="opaque202209238">
    <color rgba="0.792156862745098 0.8196078431372549 0.9333333333333333 1.0"/>
  </material>
  <material name="steel_satin">
    <color rgba="0.6274509803921569 0.6274509803921569 0.6274509803921569 1.0"/>
  </material>
  <material name="opaque262626">
    <color rgba="0.10196078431372549 0.10196078431372549 0.10196078431372549 1.0"/>
  </material>
  <material name="opaque192192192">
    <color rgba="0.7529411764705882 0.7529411764705882 0.7529411764705882 1.0"/>
  </material> -->

  <link name="base_link">
    <!-- <inertial>
      <origin rpy="0 0 0" xyz="0.0019681519560686657 -0.0003661037568883935 0.17864325963808905"/>
      <mass value="196.77331533757717"/>
      <inertia ixx="17.395543" ixy="0.054308" ixz="0.000249" iyy="94.223544" iyz="-4.6e-05" izz="109.901608"/>
    </inertial>
    <visual>
      <origin rpy="0 0 0" xyz="0 0 0"/>
      <geometry>
        <mesh filename="package://mecanum_bot_description/meshes/base_link.stl" scale="0.001 0.001 0.001"/>
      </geometry>
      <material name="steel_satin"/>
    </visual>
    <collision>
      <origin rpy="0 0 0" xyz="0 0 0"/>
      <geometry>
        <mesh filename="package://mecanum_bot_description/meshes/base_link.stl" scale="0.001 0.001 0.001"/>
      </geometry>
    </collision> -->
  </link>

  <link name="stacker">
    <!-- <inertial>
      <origin rpy="0 0 0" xyz="0.0019681519560686657 -0.0003661037568883935 0.17864325963808905"/>
      <mass value="196.77331533757717"/>
      <inertia ixx="17.395543" ixy="0.054308" ixz="0.000249" iyy="94.223544" iyz="-4.6e-05" izz="109.901608"/>
    </inertial>
    <visual>
      <origin rpy="0 0 0" xyz="0 0 0"/>
      <geometry>
        <mesh filename="package://mecanum_bot_description/meshes/stacker.STL" scale="0.001 0.001 0.001"/>
      </geometry>
      <material name="steel_satin"/>
    </visual>
    <collision>
      <origin rpy="0 0 0" xyz="0 0 0"/>
      <geometry>
        <mesh filename="package://mecanum_bot_description/meshes/stacker.STL" scale="0.001 0.001 0.001"/>
      </geometry>
    </collision> -->
  </link>

  <link name="rslidarfront">
    <!-- <inertial>
      <origin rpy="0 0 0" xyz="-0.005913338897972187 -0.00012108948136252407 7.10601328612892e-08"/>
      <mass value="1.166499428677959"/>
      <inertia ixx="0.000482" ixy="-3e-06" ixz="0.0" iyy="0.000539" iyz="-0.0" izz="0.000544"/>
    </inertial>
    <visual>
      <origin rpy="0 0 0" xyz="-1.316 0.3855 -0.217"/>
      <geometry>
        <mesh filename="package://mecanum_bot_description/meshes/rslidarfront.stl" scale="0.001 0.001 0.001"/>
      </geometry>
      <material name="opaque262626"/>
    </visual>
    <collision>
      <origin rpy="0 0 0" xyz="-1.316 0.3855 -0.217"/>
      <geometry>
        <mesh filename="package://mecanum_bot_description/meshes/rslidarfront.stl" scale="0.001 0.001 0.001"/>
      </geometry>
    </collision> -->
  </link>

  <link name="rslidarback">
    <!-- <inertial>
      <origin rpy="0 0 0" xyz="0.005913338897972187 0.00012108948136252407 7.10601328612892e-08"/>
      <mass value="1.1664994286779586"/>
      <inertia ixx="0.000482" ixy="-3e-06" ixz="-0.0" iyy="0.000539" iyz="0.0" izz="0.000544"/>
    </inertial>
    <visual>
      <origin rpy="0 0 0" xyz="1.316 -0.3855 -0.217"/>
      <geometry>
        <mesh filename="package://mecanum_bot_description/meshes/rslidarback.stl" scale="0.001 0.001 0.001"/>
      </geometry>
      <material name="opaque262626"/>
    </visual>
    <collision>
      <origin rpy="0 0 0" xyz="1.316 -0.3855 -0.217"/>
      <geometry>
        <mesh filename="package://mecanum_bot_description/meshes/rslidarback.stl" scale="0.001 0.001 0.001"/>
      </geometry>
    </collision> -->
  </link>

  <link name="rslidarleft">
    <!-- <inertial>
      <origin rpy="0 0 0" xyz="7.106013285351765e-08 -0.005913338897971965 -0.0001210894813626906"/>
      <mass value="1.1664994286779589"/>
      <inertia ixx="0.000544" ixy="0.0" ixz="-0.0" iyy="0.000482" iyz="-3e-06" izz="0.000539"/>
    </inertial>
    <visual>
      <origin rpy="0 0 0" xyz="-0.0 -0.4445 -0.217"/>
      <geometry>
        <mesh filename="package://mecanum_bot_description/meshes/rslidarleft.stl" scale="0.001 0.001 0.001"/>
      </geometry>
      <material name="opaque262626"/>
    </visual>
    <collision>
      <origin rpy="0 0 0" xyz="-0.0 -0.4445 -0.217"/>
      <geometry>
        <mesh filename="package://mecanum_bot_description/meshes/rslidarleft.stl" scale="0.001 0.001 0.001"/>
      </geometry>
    </collision> -->
  </link>

  <link name="rslidarright">
    <!-- <inertial>
      <origin rpy="0 0 0" xyz="7.106013285351765e-08 0.00591333889797202 0.00012108948136260733"/>
      <mass value="1.166499428677959"/>
      <inertia ixx="0.000544" ixy="-0.0" ixz="0.0" iyy="0.000482" iyz="-3e-06" izz="0.000539"/>
    </inertial>
    <visual>
      <origin rpy="0 0 0" xyz="-0.0 0.4445 -0.217"/>
      <geometry>
        <mesh filename="package://mecanum_bot_description/meshes/rslidarright.stl" scale="0.001 0.001 0.001"/>
      </geometry>
      <material name="opaque262626"/>
    </visual>
    <collision>
      <origin rpy="0 0 0" xyz="-0.0 0.4445 -0.217"/>
      <geometry>
        <mesh filename="package://mecanum_bot_description/meshes/rslidarright.stl" scale="0.001 0.001 0.001"/>
      </geometry>
    </collision> -->
  </link>

  <link name="rail_back_left">
    <!-- <inertial>
      <origin rpy="0 0 0" xyz="-9.103828801926284e-15 0.10228150541900818 -1.3877787807814457e-16"/>
      <mass value="20.159438423008275"/>
      <inertia ixx="0.088593" ixy="-0.0" ixz="0.0" iyy="0.07931" iyz="-0.0" izz="0.088593"/>
    </inertial>
    <visual>
      <origin rpy="0 0 0" xyz="1.0865 -0.2205 -0.127"/>
      <geometry>
        <mesh filename="package://mecanum_bot_description/meshes/rail_back_left.stl" scale="0.001 0.001 0.001"/>
      </geometry>
      <material name="opaque192192192"/>
    </visual>
    <collision>
      <origin rpy="0 0 0" xyz="1.0865 -0.2205 -0.127"/>
      <geometry>
        <mesh filename="package://mecanum_bot_description/meshes/rail_back_left.stl" scale="0.001 0.001 0.001"/>
      </geometry>
    </collision> -->
  </link>

  <link name="rail_front_right">
    <!-- <inertial>
      <origin rpy="0 0 0" xyz="-9.769962616701378e-15 -0.10228150541900818 -6.661338147750939e-16"/>
      <mass value="20.159438423008268"/>
      <inertia ixx="0.088593" ixy="0.0" ixz="-0.0" iyy="0.07931" iyz="-0.0" izz="0.088593"/>
    </inertial>
    <visual>
      <origin rpy="0 0 0" xyz="-1.0865 0.2205 -0.127"/>
      <geometry>
        <mesh filename="package://mecanum_bot_description/meshes/rail_front_right.stl" scale="0.001 0.001 0.001"/>
      </geometry>
      <material name="opaque192192192"/>
    </visual>
    <collision>
      <origin rpy="0 0 0" xyz="-1.0865 0.2205 -0.127"/>
      <geometry>
        <mesh filename="package://mecanum_bot_description/meshes/rail_front_right.stl" scale="0.001 0.001 0.001"/>
      </geometry>
    </collision> -->
  </link>

  <link name="rail_front_left">
    <!-- <inertial>
      <origin rpy="0 0 0" xyz="-9.103828801926284e-15 0.10228150541900818 7.494005416219807e-16"/>
      <mass value="20.159438423008268"/>
      <inertia ixx="0.088593" ixy="-0.0" ixz="0.0" iyy="0.07931" iyz="-0.0" izz="0.088593"/>
    </inertial>
    <visual>
      <origin rpy="0 0 0" xyz="-1.0865 -0.2205 -0.127"/>
      <geometry>
        <mesh filename="package://mecanum_bot_description/meshes/rail_front_left.stl" scale="0.001 0.001 0.001"/>
      </geometry>
      <material name="opaque192192192"/>
    </visual>
    <collision>
      <origin rpy="0 0 0" xyz="-1.0865 -0.2205 -0.127"/>
      <geometry>
        <mesh filename="package://mecanum_bot_description/meshes/rail_front_left.stl" scale="0.001 0.001 0.001"/>
      </geometry>
    </collision> -->
  </link>

  <link name="rail_back_right">
    <!-- <inertial>
      <origin rpy="0 0 0" xyz="-9.769962616701378e-15 -0.10228150541900818 -6.661338147750939e-16"/>
      <mass value="20.159438423008268"/>
      <inertia ixx="0.088593" ixy="0.0" ixz="0.0" iyy="0.07931" iyz="-0.0" izz="0.088593"/>
    </inertial>
    <visual>
      <origin rpy="0 0 0" xyz="1.0865 0.2205 -0.127"/>
      <geometry>
        <mesh filename="package://mecanum_bot_description/meshes/rail_back_right.stl" scale="0.001 0.001 0.001"/>
      </geometry>
      <material name="opaque192192192"/>
    </visual>
    <collision>
      <origin rpy="0 0 0" xyz="1.0865 0.2205 -0.127"/>
      <geometry>
        <mesh filename="package://mecanum_bot_description/meshes/rail_back_right.stl" scale="0.001 0.001 0.001"/>
      </geometry>
    </collision> -->
  </link>

  <link name="Omniwheel_1_v3_1">
    <!-- <inertial>
      <origin rpy="0 0 0" xyz="-4.348036242163289e-08 -0.07300002486069174 -3.7621899460521524e-05"/>
      <mass value="31.32979094487986"/>
      <inertia ixx="0.169702" ixy="-0.0" ixz="-0.0" iyy="0.251126" iyz="0.0" izz="0.169729"/>
    </inertial>
    <visual>
      <origin rpy="0 0 0" xyz="-0.814 0.3165 -0.10875"/>
      <geometry>
        <mesh filename="package://mecanum_bot_description/meshes/Omniwheel_1_v3_1.stl" scale="0.001 0.001 0.001"/>
      </geometry>
      <material name="opaque202209238"/>
    </visual>
    <collision>
      <origin rpy="0 0 0" xyz="-0.814 0.3165 -0.10875"/>
      <geometry>
        <mesh filename="package://mecanum_bot_description/meshes/Omniwheel_1_v3_1.stl" scale="0.001 0.001 0.001"/>
      </geometry>
    </collision> -->
  </link>
  
  <link name="Omniwheel_2_v2_1">
    <!-- <inertial>
      <origin rpy="0 0 0" xyz="2.5076084986253022e-08 0.07299999877599006 -3.760045846996907e-05"/>
      <mass value="31.32979913770676"/>
      <inertia ixx="0.169702" ixy="0.0" ixz="-0.0" iyy="0.251126" iyz="-0.0" izz="0.169729"/>
    </inertial>
    <visual>
      <origin rpy="0 0 0" xyz="-0.814 -0.3165 -0.10875"/>
      <geometry>
        <mesh filename="package://mecanum_bot_description/meshes/Omniwheel_2_v2_1.stl" scale="0.001 0.001 0.001"/>
      </geometry>
      <material name="opaque202209238"/>
    </visual>
    <collision>
      <origin rpy="0 0 0" xyz="-0.814 -0.3165 -0.10875"/>
      <geometry>
        <mesh filename="package://mecanum_bot_description/meshes/Omniwheel_2_v2_1.stl" scale="0.001 0.001 0.001"/>
      </geometry>
    </collision> -->
  </link>

  <link name="Omniwheel_2_v2_2">
    <!-- <inertial>
      <origin rpy="0 0 0" xyz="2.5076084653186115e-08 -0.07300000122400974 -3.7600458469913556e-05"/>
      <mass value="31.32979913770676"/>
      <inertia ixx="0.169702" ixy="0.0" ixz="-0.0" iyy="0.251126" iyz="-0.0" izz="0.169729"/>
    </inertial>
    <visual>
      <origin rpy="0 0 0" xyz="0.814 0.3165 -0.10875"/>
      <geometry>
        <mesh filename="package://mecanum_bot_description/meshes/Omniwheel_2_v2_2.stl" scale="0.001 0.001 0.001"/>
      </geometry>
      <material name="opaque202209238"/>
    </visual>
    <collision>
      <origin rpy="0 0 0" xyz="0.814 0.3165 -0.10875"/>
      <geometry>
        <mesh filename="package://mecanum_bot_description/meshes/Omniwheel_2_v2_2.stl" scale="0.001 0.001 0.001"/>
      </geometry>
    </collision> -->
  </link>

  <link name="Omniwheel_1_v3_2">
    <!-- <inertial>
      <origin rpy="0 0 0" xyz="4.34803449911314e-08 0.07300002486069151 -3.76218994605354e-05"/>
      <mass value="31.32979094487986"/>
      <inertia ixx="0.169702" ixy="-0.0" ixz="0.0" iyy="0.251126" iyz="-0.0" izz="0.169729"/>
    </inertial>
    <visual>
      <origin rpy="0 0 0" xyz="0.814 -0.3165 -0.10875"/>
      <geometry>
        <mesh filename="package://mecanum_bot_description/meshes/Omniwheel_1_v3_2.stl" scale="0.001 0.001 0.001"/>
      </geometry>
      <material name="opaque202209238"/>
    </visual>
    <collision>
      <origin rpy="0 0 0" xyz="0.814 -0.3165 -0.10875"/>
      <geometry>
        <mesh filename="package://mecanum_bot_description/meshes/Omniwheel_1_v3_2.stl" scale="0.001 0.001 0.001"/>
      </geometry>
    </collision> -->
  </link>

  <link name="e1r_rslidarfront">
  </link>

  <link name="2dlidar">
  </link>

  <link name="e1r_lidar_transformed">
  </link>

  <link name="dummy_lidar">
  </link>

  <link name="rslidartop">
  </link>


  <!-- <joint name="joint_rslidarback" type="fixed"> -->
    <!-- <origin rpy="0.0349066 0 0" xyz="-1.316 0.3855 0.217"/> -->
    <!-- <origin rpy="0 0 1.57" xyz="-1.2954 0.3971 0.34706"/>
    <child link="rslidarback"/>
    <parent link="base_link"/>
  </joint> -->
  <!-- <joint name="joint_rslidarfront" type="fixed"> -->
    <!-- <origin rpy="0 0 0" xyz="1.316 -0.3855 0.217"/> -->
    <!-- <origin rpy="-0.0436332 -0.0174533 0" xyz="1.316 -0.3855 0.217"/> -->
    <!-- <origin rpy="-0.0296706 0.01745 0" xyz="1.316 -0.3855 0.267"/> -->
    <!-- <origin rpy="0 0 -0.872665" xyz="1.2954 -0.3971 0.3706"/>
    <child link="rslidarfront"/>
    <parent link="base_link"/>
  </joint> -->

  <joint name="joint_rslidarback" type="fixed">
    <!-- old values: -->
    <!-- <origin rpy="0.0349066 0 0" xyz="-1.316 0.3855 0.217"/> -->
    <!-- <origin rpy="0 0 1.57" xyz="-1.312 0.44 0.345"/> -->
    <!-- calibrated 2026-03-25 (bag: new_calibrated_rz_20260324_190930, GICP fitness=0.300, rmse=0.123m): -->
    <origin rpy="-0.021332 -0.006262 2.367128" xyz="-1.263870 0.549682 0.247603"/>
    <child link="rslidarback"/>
    <parent link="base_link"/>
  </joint>
  <joint name="joint_rslidarfront" type="fixed">
    <!-- old values: -->
    <!-- <origin rpy="0 0 0" xyz="1.316 -0.3855 0.217"/> -->
    <!-- <origin rpy="-0.0436332 -0.0174533 0" xyz="1.316 -0.3855 0.217"/> -->
    <!-- <origin rpy="-0.0296706 0.01745 0" xyz="1.316 -0.3855 0.267"/> -->
    <!-- <origin rpy="0 0 -0.872665" xyz="1.312 -0.44 0.345"/> -->
    <!-- from bag tf_static 2026-03-25 (reference / calibration initial guess): -->
    <origin rpy="0.0 0.0 -0.820000" xyz="1.312 -0.45 0.345"/>
    <child link="rslidarfront"/>
    <parent link="base_link"/>
  </joint>

  <joint name="joint_rslidarleft" type="fixed">
    <origin rpy="0 -0.0174533 0" xyz="0.0 0.4445 0.217"/>
    <parent link="base_link"/>
    <child link="rslidarleft"/>
  </joint>

  <joint name="joint_rslidarright" type="fixed">
    <origin rpy="0 0.0261799 0" xyz="0.0 -0.4445 0.217"/>
    <parent link="base_link"/>
    <child link="rslidarright"/>
  </joint>

  <joint name="joint_e1r_rslidarfront" type="fixed">
    <origin rpy="0 0 0" xyz="1.316 0.3855 0.217"/>
    <parent link="base_link"/>
    <child link="e1r_rslidarfront"/>
  </joint>

  <joint name="2dlidar_joint" type="fixed">
    <origin rpy="0 0 0" xyz="0 0 0"/>
    <parent link="base_link"/>
    <child link="2dlidar"/>
  </joint>

  <joint name="joint_e1r_lidar_transformed" type="fixed">
    <origin rpy="0 0 0" xyz="1.316 0.0 0.217"/>
    <parent link="base_link"/>
    <child link="e1r_lidar_transformed"/>
  </joint>
 
  <joint name="joint_dummy_lidar" type="fixed">
    <!-- <origin rpy="0 0 -1.57" xyz="1.316 0.0 0.335"/> -->
    <origin rpy="0 0 0" xyz="1.316 0.0 0.343"/>
    <parent link="base_link"/>
    <child link="dummy_lidar"/>
  </joint>

  <joint name="joint_rslidartop" type="fixed">
    <origin rpy="0 0 3.14" xyz="-0.15 0 2.18"/>
    <parent link="base_link"/>
    <child link="rslidartop"/>
  </joint>


  <joint name="Revolute 5" type="continuous">
    <origin rpy="0 0 0" xyz="-1.0865 0.2205 0.127"/>
    <parent link="base_link"/>
    <child link="rail_back_left"/>
    <axis xyz="0.0 1.0 0.0"/>
  </joint>

  <joint name="Revolute 6" type="continuous">
    <origin rpy="0 0 0" xyz="1.0865 -0.2205 0.127"/>
    <parent link="base_link"/>
    <child link="rail_front_right"/>
    <axis xyz="0.0 -1.0 0.0"/>
  </joint>

  <joint name="Revolute 7" type="continuous">
    <origin rpy="0 0 0" xyz="1.0865 0.2205 0.127"/>
    <parent link="base_link"/>
    <child link="rail_front_left"/>
    <axis xyz="0.0 1.0 0.0"/>
  </joint>

  <joint name="Revolute 8" type="continuous">
    <origin rpy="0 0 0" xyz="-1.0865 -0.2205 0.127"/>
    <parent link="base_link"/>
    <child link="rail_back_right"/>
    <axis xyz="0.0 -1.0 0.0"/>
  </joint>

  <joint name="Revolute 9" type="continuous">
    <origin rpy="0 0 0" xyz="0.814 -0.3165 0.10875"/>
    <parent link="base_link"/>
    <child link="Omniwheel_1_v3_1"/>
    <axis xyz="0.0 -1.0 0.0"/>
  </joint>

  <joint name="Revolute 10" type="continuous">
    <origin rpy="0 0 0" xyz="0.814 0.3165 0.10875"/>
    <parent link="base_link"/>
    <child link="Omniwheel_2_v2_1"/>
    <axis xyz="0.0 1.0 0.0"/>
  </joint>

  <joint name="Revolute 11" type="continuous">
    <origin rpy="0 0 0" xyz="-0.814 -0.3165 0.10875"/>
    <parent link="base_link"/>
    <child link="Omniwheel_2_v2_2"/>
    <axis xyz="0.0 -1.0 0.0"/>
  </joint>

  <joint name="Revolute 12" type="continuous">
    <origin rpy="0 0 0" xyz="-0.814 0.3165 0.10875"/>
    <parent link="base_link"/>
    <child link="Omniwheel_1_v3_2"/>
    <axis xyz="0.0 1.0 0.0"/>
  </joint>

  <joint name="stacker_joint" type="fixed">
    <origin rpy="0 0 0" xyz="0.0 0 0.40"/>
    <parent link="base_link"/>
    <child link="stacker"/>
  </joint>

</robot>
